## 四、异常

在面向过程的C语言里，处理错误的方式主要是返回错误码，比如成功就返回0，失败就返回相应的错误码。但这种方式是有缺陷的，比如一些有返回值的函数，它返回0和-1都是有效的数值，但我们又要拿0和-1来表征成功和失败，那外界使用时就会产生歧义。

而异常是面向对象语言里处理错误的一种方式，它不存在返回错误码方式的缺陷，而且还可以包含更丰富的错误信息，也就是说使用抛异常的方式来处理错误更加面向对象。

#### 1、开发中的错误

在开发程序的过程中，会遇到各种各样的错误，错误主要分为三类：

* 语法错误：比如我们把一个string类型赋值给int类型【int i = "ABC";】，C++语法就不允许你这么干，这就是语法错误，语法错误会导致编译报错，程序根本就运行不起来

* 逻辑错误：比如我们本来想让【i += 1】的，但是不小心写成了【i -= 1】，从而导致结果出错了，这就是逻辑错误，逻辑错误编译是能通过的，程序也能运行起来，只不过程序运行时会有bug，但程序不会崩溃

* 异常：比如堆OOM了、空指针了、数组越界了等等，这些都是在程序运行过程中才产生的意外，这就是异常，异常编译是能通过的，程序也能运行起来，只不过异常如果没被处理的话程序运行时会崩溃


```c++
// 堆OOM举例
void test() {
    // 比如我们要申请一段连续的堆内存，堆内存总共才多大啊，我们却要100000000000000 * 4个字节
    // 编译是不会报错的，程序也能跑起来，但是执行到这就崩了，因为堆OOM了
    //
    // libc++abi: terminating with uncaught exception of type std::bad_alloc: std::bad_alloc
    int *p = new int[100000000000000];
    delete[] p;
}

int main() {
    test();
    
    return 0;
}
```

```c++
// 空指针举例
void test() {
    // 比如我们访问一个空指针
    // 编译是不会报错的，程序也能跑起来，但是执行到这就崩了，因为C++里是不允许访问空指针的
    //
    // BAD_ACCESS
    int *p = nullptr;
    *p = 10;
}

int main() {
    test();
    
    return 0;
}
```

```c++
#include <iostream>
#include <vector>
using namespace std;

int main() {
    vector<int> v = { 1, 2, 3 };
    // libc++abi: terminating with uncaught exception of type std::out_of_range: vector
    cout << v.at(3) << endl;

    return 0;
}
```

#### 2、捕获异常

程序产生了异常，我们一般称之为：抛出了异常，我们可以通过try-catch来捕获异常并处理。

> try {
>     // 把可能会抛出异常的代码写在try里
> } catch (const exception &e) { // 捕获C++标准异常，C++标准异常都继承自exception类
>     // 然后在catch里看看你想对异常做些什么处理：
>     
>
> ​	// 打印异常描述
> ​	cout << e.what() << endl;
>
> ​	// 一些其它的处理
> ​	// ...
>
> } catch (const 自定义异常类型 &e) { // 捕获自定义异常
>     // 然后在catch里看看你想对异常做些什么处理：
>
> ​    // 打印异常描述
> ​	// cout << e.what() << endl;
>
> ​	// 一些其它的处理
> ​	// ...
>
> }

```c++
#include <iostream>
using namespace std;

void test() {
    int *p = new int[100000000000000];
    delete[] p;
}

int main() {
  	// 通过try-catch来处理异常
    try {
        test();
    } catch (const exception &e) {
        cout << e.what() << endl; // std::bad_alloc
    }
    
    return 0;
}
```

#### 3、自定义异常、抛出异常

C++标准异常会在某些情况下自动抛出，除此之外我们还可以自定义异常并抛出。

```c++
#include <iostream>
using namespace std;

// 所有异常的基类
class Exception {
public:
    int m_errCode;
    const string &m_errMsg;
    
    Exception(int errCode, const string &errMsg)
    :   m_errCode(errCode),
        m_errMsg(errMsg)
    {}
    
    virtual string what() const = 0;
};

// 除法异常
class DiviException : public Exception {
public:
    DiviException(int errCode, const string &errMsg) : Exception(errCode, errMsg) {}
    
    string what() const {
        return "除法异常：" + to_string(m_errCode) + " " + m_errMsg;
    }
};

int divi(int i1, int i2) {
    // 顺带说一下这里我们为什么要抛出异常
    // 其实我们在编写代码的时候，对于一些意外，可以有多种处理方式
    // 比如这里如果i2为0，我们也可以返回一个特殊的值如-1来代表出错了，但是这种处理方式好像不太适合这个场景，因为-1完全有可能是个有效的返回值
    // 因此我们才选择了抛出异常
  	// 同时使用抛异常的方式来处理错误更加面向对象
    if (i2 == 0) {
        throw DiviException(-1, "除数不能为0");
    }
    
    return i1 / i2;
}

int main() {
    try {
        divi(10, 0);
    } catch (const Exception &e) {
        cout << e.what() << endl; // 除法异常：-1 除数不能为0
    }
    
    return 0;
}
```
